"""
Call analysis and AI processing background tasks
"""
from celery import current_task
from app.celery_app import celery_app
from app.services.uwc_client import UWCClient
from app.core.pii_masking import PIISafeLogger
import logging

logger = PIISafeLogger(__name__)

@celery_app.task(bind=True, max_retries=3)
def analyze_call_transcript(self, transcript: str, call_id: str, tenant_id: str):
    """
    Analyze call transcript for coaching insights, objections, and SOP compliance
    """
    try:
        logger.info(f"Starting call analysis for call {call_id}")
        
        uwc_client = UWCClient()
        
        # Analyze using UWC RAG
        try:
            analysis_result = uwc_client.query_rag(
                query=f"Analyze this call transcript for coaching insights: {transcript}",
                tenant_id=tenant_id
            )
            
            if analysis_result:
                logger.info(f"UWC analysis successful for call {call_id}")
                return {
                    "success": True,
                    "provider": "uwc",
                    "analysis": analysis_result,
                    "call_id": call_id,
                    "tenant_id": tenant_id
                }
        except Exception as e:
            logger.warning(f"UWC analysis failed for call {call_id}: {str(e)}")
        
        # Fallback to local analysis
        fallback_analysis = {
            "objections_detected": [],
            "coaching_opportunities": [],
            "sop_compliance": "unknown",
            "sentiment": "neutral",
            "key_points": [],
            "recommendations": []
        }
        
        logger.info(f"Using fallback analysis for call {call_id}")
        return {
            "success": True,
            "provider": "fallback",
            "analysis": fallback_analysis,
            "call_id": call_id,
            "tenant_id": tenant_id
        }
        
    except Exception as e:
        logger.error(f"Call analysis failed for call {call_id}: {str(e)}")
        raise self.retry(countdown=60 * (2 ** self.request.retries))

@celery_app.task
def generate_daily_reports():
    """
    Generate daily performance reports for all tenants
    """
    logger.info("Generating daily reports")
    # Implementation for daily reports
    pass

@celery_app.task(bind=True, max_retries=3)
def batch_analyze_calls(self, call_ids: list, tenant_id: str):
    """
    Batch analyze multiple calls for efficiency
    """
    try:
        logger.info(f"Starting batch analysis for {len(call_ids)} calls")
        
        results = []
        for call_id in call_ids:
            # Process each call
            result = analyze_call_transcript.delay("", call_id, tenant_id)
            results.append(result)
        
        return {
            "success": True,
            "total_calls": len(call_ids),
            "results": results,
            "tenant_id": tenant_id
        }
        
    except Exception as e:
        logger.error(f"Batch analysis failed: {str(e)}")
        raise self.retry(countdown=60 * (2 ** self.request.retries))
